Workbook
Name __________GoA1: __________GoA1
Name _________GoA1: _________GoA1
Name _______GoA1: _______GoA1
Name ______GoA1: ______GoA1
Name _____GoA1: _____GoA1
Name ____GoA1: ____GoA1
Name ___GoA1: ___GoA1
Name __GoA1: __GoA1
Name _GoA1: _GoA1
Name _ML1: [2]分类数据!$C$3
Name _ML10: [2]分类数据!$C$12
Name _ML2: [2]分类数据!$C$4
Name _ML3: [2]分类数据!$C$5
Name _ML4: [2]分类数据!$C$6
Name _ML5: [2]分类数据!$C$7
Name _ML6: [2]分类数据!$C$8
Name _ML7: [2]分类数据!$C$9
Name _ML8: [2]分类数据!$C$10
Name _ML9: [2]分类数据!$C$11
Name a_: #REF!
Name a_A: #REF!
Name a_LED: #REF!
Name a_Mic: #REF!
Name a_Opti: #REF!
Name A_Plug: #REF!
Name ASIL: #REF!
Name b_: #REF!
Name b_F: #REF!
Name b_LED: #REF!
Name b_Mic: #REF!
Name b_Opti: #REF!
Name B_Plug: #REF!
Name BiCMOS: #REF!
Name Bipolar: #REF!
Name c_: #REF!
Name C_Coax: #REF!
Name c_Fibr: #REF!
Name c_G: #REF!
Name c_Las: #REF!
Name c_Opti: #REF!
Name C_Value: #REF!
Name Capture.Capture: #N/A
Name CMOS: #REF!
Name CMRight: [3]信息定义!$L$6:$L$10
Name Comm: #REF!
Name Compliance2: '[5]Comp Matrix - Adblue'!$N$5:$N$8
Name cont_range: #REF!
Name Control: #REF!
Name CT: '[6]Hazard Assessment'!$U$2:$U$6
Name d_: #REF!
Name d_DCF_: #REF!
Name d_Las: #REF!
Name d_T: #REF!
Name e.total: [8]同行评审!$M$8
Name e_: #REF!
Name e_A: #REF!
Name e_LED: #REF!
Name e_Opti: #REF!
Name E_Value: #REF!
Name effort.ta: [9]引言!#REF!

Sheet 封面
C1: SW FMEA && DFA报告 | H1: 模板编号/版本: AR/SR-0908-007-V0
A2: 项目编号 | C2: C255-10 | D2: 版本号 | E2: V1.0 | F2: 发布日期 | G2: =B37 | H2: 页数 | I2: 1/1
A3: C255-10 SW FMEA && DFA报告
A34: 发布部门 | B34: 技术课 | E34: 保密等级 | G34: □绝密 ■机密 □秘密 □公开
A35: 作者 | B35: 罗映荣 | D35: 审核 | E35: 崔之文 | G35: 批准 | H35: 王东宏
A36: 角色 | B36: 安全员 | D36: 角色 | E36: 安全经理 | G36: 角色 | H36: 项目总监
A37: 日期 | B37: 45920 | D37: 日期 | E37: 45939 | G37: 日期 | H37: 45945
A44: 备注：版权属芜湖安瑞光电有限公司所有，本文档内容属商业机密。未经允许，任何组织或个人不得以任何形式复制和传播。

Sheet 变更履历
A1: 变更履历 / Change History
A3: 版本Version | B3: 状态 Status | C3: 编制人Author | D3: 编制日期 Date | E3: 批准人Approver | F3: 批准日期Approve Date | G3: 内容描述 Description
A4: V1.0 | B4: Released | C4: 罗映荣 | D4: =封面!B37 | E4: 崔之文 | F4: =封面!E37 | G4: 首次编制

Sheet General
A1: 1 文档目的 / Document Purpose
B2: This document aims at: a) provide evidence for the suitability of the software to provide the specified safety-related functions and properties as required by the respective ASIL; b) identify or confirm the safety-related parts of the software; and c) support the specification and verify the effectiveness of the safety measures.
A8: 2 输入文档 / Input
B9: 序号 | C9: 文档名称 | D9: 文档版本 | E9: 文档日期
B10: No. | C10: Document Name | D10: Version | E10: Date
B11: 1 | C11: C255-10后组合灯软件架构设计规范 | D11: V1.2
A13: 3 参考文档 / reference
B14: 序号 | C14: 文档名称 | D14: 文档版本 | E14: 文档日期
B15: No. | C15: Document Name | D15: Version | E15: Date
B16: 1 | C16: ISO26262-2018
A18: 4 术语和缩写
B19: 序号 | C19: 术语/缩略语 | D19: 描述
B20: No. | C20: Terms and Abbreviation | D20: description
B21: 1 | C21: DFA | D21: Dependent Failure Analysis，依存失效分析
B22: 2 | C22: FFI | D22: Freedom From Interference，免于干扰
B23: 3 | C23: CCF | D23: Common Cause Failure，共因失效
B24: 4 | C24: CF | D24: Cascading Failure，级联失效
B25: 5 | C25: ASIL | D25: Automotive Safety Integrity Level，汽车安全完整性等级
B26: 6 | C26: SWC | D26: Software Component，软件组件
B27: 7 | C27: SG | D27: Safety Goal，安全目标
B28: 8 | C28: BCC | D28: Byte Counter Check，字节计数校验(E2E)

Sheet SW Arch
A1: 软件架构图和分析范围（也可引用软件架构设计规范）
A2: 虚线框内，为本分析的范围。
A6: Layer | B6: Component ID | C6: Component Name | D6: Period | E6: ASIL | F6: Component description
A7: ASW | B7: SWC-1 | C7: ECU_PosBreak | D7: 1ms | E7: ASILB | F7: 位置制动控制
B8: SWC-2 | C8: ECU_TurnLight | D8: 1ms | E8: ASILA | F8: 转向灯控制
B9: SWC-3 | C9: ECU_ReverseLight | D9: 1ms | E9: ASILA | F9: 倒车灯控制
B10: SWC-4 | C10: ECU_LicenseLight | D10: 1ms | E10: QM | F10: 牌照灯控制
B11: SWC-5 | C11: ECU_Voltage | D11: 1ms | E11: ASILB | F11: 电压管理
B12: SWC-6 | C12: ECU_LampSignalDec | D12: 1ms | E12: QM | F12: 仪式感
B13: SWC-7 | C13: BCC | D13: / | E13: ASILB | F13: E2E校验
B14: SWC-8 | C14: LinkerTimeOut | D14: 1ms | E14: ASILB | F14: 报文在线监测
B15: SWC-9 | C15: FailSafe | D15: 1ms | E15: ASILB | F15: 故障处理
B16: SWC-10 | C16: NM_Management | D16: 1ms | E16: QM | F16: 网络管理
A17: BSW | B17: SWC-11 | C17: CANBusOffDeal | D17: 1ms | E17: ASILB | F17: CAN BusOff时的快慢恢复机制
B18: SWC-12 | C18: CANReceive | D18: / | E18: ASILB | F18: CAN信号接收
B19: SWC-13 | C19: CANTrans | D19: 20ms | E19: ASILB | F19: CAN信号发送
B20: SWC-14 | C20: UDS Server | D20: 1ms | E20: QM | F20: 统一诊断服务
B21: SWC-15 | C21: EepromDriver | D21: 1ms | E21: ASILA | F21: 外部eeprom驱动控制
B22: SWC-16 | C22: DEM | D22: 10ms | E22: ASILB | F22: 故障诊断码管理
B23: SWC-17 | C23: SysClk | D23: 1ms | E23: ASILA | F23: 系统时钟控制
B24: SWC-18 | C24: SPI | D24: 1ms | E24: ASILA | F24: SPI驱动控制
B25: SWC-19 | C25: CAN | D25: 1ms | E25: ASILB | F25: CAN驱动控制
B26: SWC-20 | C26: ADC | D26: 1ms | E26: ASILB | F26: ADC驱动控制
B27: SWC-21 | C27: WDG | D27: 100ms | E27: ASILB | F27: 看门狗处理
B28: SWC-22 | C28: GPIO | D28: 1ms | E28: ASILB | F28: IO控制
B29: SWC-23 | C29: PWM | D29: 1ms | E29: ASILB | F29: PWM驱动控制
B30: SWC-24 | C30: NVM | D30: 1ms | E30: ASILB | F30: 非易失性存储管理

Sheet Combination matrix
C2: SysClk | D2: SPI | E2: CAN | F2: ADC | G2: WDG | H2: GPIO | I2: PWM | J2: NVM | K2: =A12 | L2: =A13 | M2: =A14 | N2: =A15 | O2: =A16 | P2: =A17 | Q2: =A18 | R2: =A19 | S2: =A20 | T2: =A21 | U2: =A22 | V2: =A23 | W2: =A24 | X2: =A25 | Y2: =A26 | Z2: =A27
C3: ASILA | D3: ASILA | E3: ASILB | F3: ASILB | G3: ASILB | H3: ASILB | I3: ASILB | J3: ASILB | K3: ASILB | L3: ASILA | M3: ASILA | N3: QM | O3: ASILB | P3: QM | Q3: ASILB | R3: ASILB | S3: ASILB | T3: QM | U3: ASILB | V3: ASILB | W3: ASILB | X3: QM | Y3: ASILA | Z3: ASILB
A4: SysClk | B4: ASILA | C4: NA | D4: SW_DF_001 | E4: SW_DF_001 | F4: SW_DF_001 | G4: SW_DF_001 | H4: SW_DF_001 | I4: SW_DF_001 | J4: SW_DF_001 | K4: / | L4: / | M4: / | N4: / | O4: / | P4: / | Q4: / | R4: / | S4: / | T4: / | U4: / | V4: / | W4: / | X4: / | Y4: / | Z4: /
A5: SPI | B5: ASILA | C5: / | D5: NA | E5: / | F5: / | G5: / | H5: / | I5: / | J5: / | K5: / | L5: / | M5: / | N5: / | O5: / | P5: / | Q5: / | R5: / | S5: / | T5: / | U5: / | V5: / | W5: / | X5: / | Y5: / | Z5: /
A6: CAN | B6: ASILB | C6: / | D6: / | E6: NA | F6: / | G6: / | H6: / | I6: / | J6: / | K6: / | L6: / | M6: / | N6: / | O6: / | P6: / | Q6: / | R6: SW_DF_002 | S6: / | T6: / | U6: SW_DF_002 | V6: / | W6: / | X6: / | Y6: / | Z6: /
A7: ADC | B7: ASILB | C7: / | D7: / | E7: / | F7: NA | G7: / | H7: / | I7: / | J7: / | K7: / | L7: / | M7: / | N7: / | O7: SW_DF_003 | P7: / | Q7: / | R7: / | S7: / | T7: / | U7: / | V7: / | W7: / | X7: / | Y7: / | Z7: /
A8: WDG | B8: ASILB | C8: / | D8: / | E8: / | F8: / | G8: NA | H8: / | I8: / | J8: / | K8: / | L8: / | M8: / | N8: / | O8: / | P8: / | Q8: / | R8: / | S8: / | T8: / | U8: / | V8: / | W8: / | X8: / | Y8: / | Z8: /
A9: GPIO | B9: ASILB | C9: / | D9: / | E9: / | F9: / | G9: / | H9: NA | I9: / | J9: / | K9: SW_DF_004 | L9: / | M9: / | N9: / | O9: / | P9: / | Q9: / | R9: / | S9: SW_DF_004 | T9: / | U9: / | V9: / | W9: / | X9: / | Y9: / | Z9: /
A10: PWM | B10: ASILB | C10: / | D10: / | E10: / | F10: / | G10: / | H10: / | I10: NA | J10: / | K10: / | L10: / | M10: / | N10: / | O10: / | P10: / | Q10: / | R10: / | S10: / | T10: / | U10: / | V10: / | W10: / | X10: / | Y10: / | Z10: /
A11: NVM | B11: ASILB | C11: / | D11: SW_DF_005 | E11: SW_DF_005 | F11: SW_DF_005 | G11: SW_DF_005 | H11: SW_DF_005 | I11: SW_DF_005 | J11: NA | K11: / | L11: / | M11: / | N11: / | O11: / | P11: / | Q11: / | R11: / | S11: / | T11: / | U11: / | V11: / | W11: / | X11: / | Y11: / | Z11: /
A12: ECU_PosBreak | B12: ASILB | C12: / | D12: / | E12: / | F12: / | G12: / | H12: / | I12: SW_DF_006 | J12: / | K12: NA | L12: / | M12: / | N12: / | O12: / | P12: / | Q12: / | R12: / | S12: / | T12: / | U12: / | V12: / | W12: SW_DF_006 | X12: / | Y12: / | Z12: /
A13: ECU_TurnLight | B13: ASILA | C13: / | D13: / | E13: / | F13: / | G13: / | H13: / | I13: SW_DF_007 | J13: / | K13: / | L13: NA | M13: / | N13: / | O13: / | P13: / | Q13: / | R13: / | S13: / | T13: / | U13: / | V13: / | W13: SW_DF_007 | X13: / | Y13: / | Z13: /
A14: ECU_ReverseLight | B14: ASILA | C14: / | D14: / | E14: / | F14: / | G14: / | H14: / | I14: SW_DF_008 | J14: / | K14: / | L14: / | M14: NA | N14: / | O14: / | P14: / | Q14: / | R14: / | S14: / | T14: / | U14: / | V14: / | W14: SW_DF_008 | X14: / | Y14: / | Z14: /
A15: ECU_LicenseLight | B15: QM | C15: / | D15: / | E15: / | F15: / | G15: / | H15: SW_DF_009 | I15: / | J15: / | K15: / | L15: / | M15: / | N15: NA | O15: / | P15: / | Q15: / | R15: / | S15: / | T15: / | U15: / | V15: / | W15: SW_DF_009 | X15: / | Y15: / | Z15: /
... A27: DEM | B27: ASILB | C27: / | D27: / | E27: / | F27: / | G27: / | H27: / | I27: / | J27: / | K27: / | L27: / | M27: / | N27: / | O27: / | P27: / | Q27: / | R27: / | S27: / | T27: / | U27: / | V27: / | W27: / | X27: / | Y27: SW_DF_021 | Z27: NA

Sheet Top Event
B1: DFA Top Event From FFI/Independent
B2: "I":Independce. [ISO26262-9-2018] Freedom from interference and absence of common cause failures are used to justify independence when performing ASIL decomposition "F":Freedom from interference. [ISO26262-9-2018] Freedom from interference is used to justify the coexistence of elements with different, or no, assigned ASIL. "O": No need to disguss. | F2: 共因 | G2: 级联
B3: Top EventID | C3: Event Description | D3: Function Description | E3: ASIL | F3: common cause failure ? | G3: cascading failure ? | H3: ﻿coexistence- Freedom from interface? | I3: — similar and dissimilar redundant elements; (功能冗余，分解) | J3: — ASIL decomposition（分解） | K3: — different functions implemented with identical software or hardware elements;(同一个集成模块） | L3: — functions and their respective safety mechanisms;（分解） | M3: — partitions of functions or software elements;(QM, ASIL FFI) | N3: — physical distance between hardware elements, with or without a barrier; and | O3: — common external resources.（按照最高等级开发）
B4: SW_DF_001 | C4: SysClk:SPI & CAN & ADC & WDG & GPIO & PWM &NVM | D4: 时钟失效的时候SPI,CAN,ADC,WDG,GPIO,PWM,NVM模块均失效 | E4: ASILA & ASILA & ASILB & ASILB & ASILB & ASILB & ASILB & ASILB | F4: Y | G4: N | H4: N | L4: Y
B5: SW_DF_002 | C5: CAN :LinkerTimeOut | D5: CAN模块失效的时候LinkerTimeOut开始进行通信丢失检测 | E5: ASILB & ASILB | F5: Y | G5: N | H5: N
B6: SW_DF_003 | C6: ADC :ECU_Voltage | D6: ADC模块失效后导致电源管理模块失效 | E6: ASILB & ASILB & ASILB | F6: N | G6: Y | H6: N
B7: SW_DF_004 | C7: GPIO:ECU_PosBreak & FailSafe | D7: GPIO模块失效后位置制动控制模块无法检测硬线制动输入; GPIO模块失效后故障检测模块无法实时检测到功能故障反馈进行故障检测和故障恢复 | E7: ASILB & ASILB & ASILB | F7: Y | G7: N | H7: N
B8: SW_DF_005 | C8: NVM:SPI & CAN & ADC & WDG & GPIO & PWM | D8: NVM模块失效后SPI,CAN,ADC,WDG,GPIO,PWM模块均失效 | E8: ASILB & ASILA & ASILB & ASILB & ASILB & ASILB & ASILB | F8: Y | G8: N | H8: N
B9: SW_DF_006 | C9: ECU_PosBreak :PWM & CANTrans | D9: 位置制动控制模块失效后无法按预期给PWM模块输入； 位置制动控制模块失效后无法给CANTrans模块输入位置制动功能状态信号和故障信号 | E9: ASILB & ASILB & ASILB | F9: N | G9: Y | H9: N
B10: SW_DF_007 | C10: ECU_TurnLight :PWM & CANTrans | D10: 转向灯控制模块失效后无法按预期给PWM模块输入； 转向控制模块失效后无法给CANTrans模块输入转向灯功能状态信号和故障信号 | E10: ASILA & ASILB & ASILB | F10: N | G10: Y | H10: N
B11: SW_DF_008 | C11: ECU_ReverseLight :PWM & CANTrans | D11: 倒车灯控制模块失效后无法给PWM模块输入导致倒车灯无法按预期点亮关闭 倒车灯控制模块失效后无法给CANTrans模块输入导致无法实时对外反馈倒车灯功能的故障和执行情况 | E11: ASILA & ASILB & ASILB | F11: N | G11: Y | H11: N
B12: SW_DF_009 | C12: ECU_LicenseLight :GPIO & CANTrans | D12: 牌照灯控制模块失效后无法给GPIO模块输入导致牌照灯无法按预期点亮关闭 牌照灯控制模块失效后无法给CANTrans模块输入导致无法实时对外反馈牌照灯功能的执行情况 | E12: QM & ASILB & ASILB | F12: N | G12: Y | H12: N
B13: SW_DF_010 | C13: ECU_Voltage:ECU_PosBreak & ECU_TurnLight & ECU_ReverseLight & ECU_LicenseLight | D13: 电源管理模块失效后可能导致电压检测异常造成位置制动控制模块，转向灯控制模块，倒车灯控制模块，牌照灯控制模块无法执行功能输出 | E13: ASILB & ASILB & ASILA & ASILA & QM | F13: N | G13: Y | H13: N
B14: SW_DF_011 | C14: ECU_LampSignalDec:PWM | D14: 仪式感模块失效后导致无法控制PWM模块实现动画效果 | E14: QM&ASILB | F14: N | G14: Y | H14: N
B15: SW_DF_012 | C15: BCC:ECU_PosBreak & ECU_TurnLight & ECU_ReverseLight & ECU_LicenseLight | D15: BCC模块失效后可能导致报文校验异常造成位置制动控制模块，转向灯控制模块，倒车灯控制模块，牌照灯控制模块无法接收CAN指令执行功能输出 | E15: ASILB & ASILB & ASILA & ASILA & QM | F15: N | G15: Y | H15: N
B16: SW_DF_013 | C16: LinkerTimeOut：ECU_PosBreak | D16: LinkerTimeOut模块失效后会导致在异常通信丢失的情况下无法检测到通信问题，传递给位置制动控制模块 | E16: ASILB & ASILB | F16: N | G16: Y | H16: N
... B24: SW_DF_021 | C24: DEM:EepromDriver | D24: 故障码管理模块失效导致无法向Eeprom传递有效故障码数据 | E24: ASILB & ASILA | F24: N | G24: Y | H24: N

Sheet SW_Safety_Analysis
A1: SW DFA
A3: ='[25]Top Event'!B4 | C3: ='Top Event'!C4 | D3: ='Top Event'!D4 | E3: ='Top Event'!E4
B4: 公式格式，误删 | C4: DF-I Category | D4: Interpretation | E4: DF-Initiator Examples | F4: Applicable? | G4: safety goal related | H4: Counter Measure | I4: Counter Measure ID | J4: Evidence | K4: sufficient? | L4: 当前是否满足,如不满足新的机制说明 | M4: Comment
A5: =A3&"_"&B5 | B5: 1 | C5: Shared resource | D5: The same software, hardware, or system element instance used by the two elements which are therefore affected by the failure or unavailability of that shared resource, i.e. from a physical perspective. | E5: Software component used by more than one other software component, e.g. – reused standard software modules 被多个其他软件组件所使用的软件组件，例如： – 重复使用的标准软件模块 | F5: Yes | G5: 系统时钟管理故障后无法输入给SPI， CAN ，ADC，WDG，GPIO， PWM，NVM时钟造成模块失效导致功能无法点亮，违背安全目标SG1,SG2.SG3 | H5: 1：支持硬线制动灯点亮： 2：支持停振检测，时钟异常时可以实时检测并尝试恢复 | I5: SW_DFA_SM_001 SW_DFA_SM_002 | J5: 通过集成测试 | K5: 满足ASILB开发和测试
A6: =A3&"_"&B6 | B6: 2 | E6: – libraries 库 | F6: not applicable
A7: =A3&"_"&B7 | B7: 3 | E7: – middleware 中间件 | F7: not applicable
A8: =A3&"_"&B8 | B8: 4 | E8: – basic software 基本软件 | F8: Yes | G8: 系统时钟管理故障后无法输入给SPI， CAN ，ADC，WDG，GPIO， PWM，NVM时钟造成模块失效导致功能无法点亮，违背安全目标SG1,SG2.SG3 | H8: 1：支持硬线制动灯点亮： 2：支持停振检测，时钟异常时可以实时检测并尝试恢复 | I8: SW_DFA_SM_001 SW_DFA_SM_002 | J8: 通过集成测试 | K8: 满足ASILB开发和测试
A9: =A3&"_"&B9 | B9: 5 | E9: – operating system including scheduler ——包含调度器的操作系统 | F9: not applicable
A10: =A3&"_"&B10 | B10: 6 | E10: – communication stack 通信协议栈 | F10: not applicable
A11: =A3&"_"&B11 | B11: 7 | E11: – parameter file参数文件 | F11: not applicable
A12: =A3&"_"&B12 | B12: 8 | E12: – execution time 执行时间 | F12: not applicable
A13: =A3&"_"&B13 | B13: 9 | E13: – allocated memory | F13: not applicable
A14: =A3&"_"&B14 | B14: 10 | C14: Components of identical type | D14: Identical components may fail with higher probability simultaneously (common mode failures) | E14: • Reused standard software modules 重复使用的标准软件模块 | F14: not applicable
A15: =A3&"_"&B15 | B15: 11 | E15: • Standard library components 标准库组件 | F15: Yes | G15: 系统时钟管理故障后无法输入给SPI， CAN ，ADC，WDG，GPIO， PWM，NVM时钟造成模块失效导致功能无法点亮，违背安全目标SG1,SG2.SG3 | H15: 1：支持硬线制动灯点亮： 2：支持停振检测，时钟异常时可以实时检测并尝试恢复 | I15: SW_DFA_SM_001 SW_DFA_SM_002 | J15: 通过集成测试 | K15: 满足ASILB开发和测试
A16: =A3&"_"&B16 | B16: 12 | E16: • Middleware 中间件 | F16: not applicable
A17: =A3&"_"&B17 | B17: 13 | E17: • Operating system 操作系统 | F17: not applicable
A18: =A3&"_"&B18 | B18: 14 | E18: • Communication stack 通信栈 | F18: not applicable
A19: =A3&"_"&B19 | B19: 15 | E19: • Parameter set 参数设置 | F19: not applicable
A20: =A3&"_"&B20 | B20: 16 | C20: Communication between the two functions | D20: Receiving function is affected by information that is false, lost, sent multiple times, or in the wrong order etc. from the sender | E20: • Information passed via argument through a function call, or via writing/reading a variable being global to the two software functions (data flow) 通过函数调用传递的信息，或者通过对全局变量的写入/读取操作（这种操作涉及两个软件函数）（数据流） | F20: not applicable
A21: =A3&"_"&B21 | B21: 17 | E21: • Data or message corruption/ repetition*/ loss*/ delay*/ masquerading or incorrect addressing of information* 数据或信息的损坏/重复/丢失/延迟/伪装或信息的错误标识* | F21: not applicable
A22: =A3&"_"&B22 | B22: 18 | E22: • Insertion*/ sequence of information* 插入* / 信息序列* | F22: not applicable
A23: =A3&"_"&B23 | B23: 19 | E23: • Corruption of information* 信息的失真* | F23: not applicable
A24: =A3&"_"&B24 | B24: 20 | E24: • Asymmetric information sent from a sender to multiple receivers* 从发送者传向多个接收者的不对称信息* | F24: not applicable
A25: =A3&"_"&B25 | B25: 21 | E25: • Information from a sender received by only a subset of the receivers* 仅部分接收者接收到的来自发送者的信息* | F25: not applicable
A26: =A3&"_"&B26 | B26: 22 | E26: • Blocking access to a communication channel* 阻止对通信通道的访问* | F26: not applicable
A27: =A3&"_"&B27 | B27: 23 | C27: Shared information inputs | D27: Same information consumed by the two functions even in absence of shared resources, i.e. from a functional perspective | E27: • Calibration parameters 标准参数 | F27: not applicable
A28: =A3&"_"&B28 | B28: 24 | E28: • Constants, or variables, being global to the two software functions 常量或变量对于这两个软件功能而言是全局性的。 | F28: not applicable
A29: =A3&"_"&B29 | B29: 25 | E29: • Basic software passes data (read from hardware register and converted into logical information) to two application software functions 基础软件会将数据（从硬件寄存器读取并转换为逻辑信息）传递给两个应用程序软件功能。 | F29: not applicable
A30: =A3&"_"&B30 | B30: 26 | E30: • Data / function parameter arguments / messages delivered by software function to more than one other function See also “Communication between the two functions” 数据/函数参数参数/软件函数传递给其他多个函数的消息 另请参阅“两个函数之间的通信” | F30: not applicable
A31: =A3&"_"&B31 | B31: 27 | C31: Environmental influences | D31: Common external environmental disturbance affects both functions | E31: System-level: mechanical shock, water ingress 系统层面：机械震动、进水 | F31: not applicable
A32: =A3&"_"&B32 | B32: 28 | E32: Software-level: not applicable for Software 软件层面：不适用于软件 | F32: not applicable
A33: =A3&"_"&B33 | B33: 29 | E33: Hardware-level: under and over voltage of the power supply 硬件层面：电源的欠压和过压情况 | F33: not applicable
A34: =A3&"_"&B34 | B34: 30 | C34: Unintended impact | D34: Two functions affecting each other’s elements directly via an implicit, that is unintended interface. | E34: • Memory / corruption of content* – “wild pointers“ (including program counter stack) 内存/内容损坏* ——“失控指针”（包括程序计数器栈 | F34: Yes | G34: 系统时钟管理故障后无法输入给SPI， CAN ，ADC，WDG，GPIO， PWM，NVM时钟造成模块失效导致功能无法点亮，违背安全目标SG1,SG2.SG3 | H34: 1：支持硬线制动灯点亮： 2：支持停振检测，时钟异常时可以实时检测并尝试恢复 3：外部狗 | I34: SW_DFA_SM_001 SW_DFA_SM_002 SW_DFA_SM_004 | J34: 通过集成测试 | K34: 满足ASILB开发和测试
A35: =A3&"_"&B35 | B35: 31 | E35: – memory mis-allocation ——内存分配错误 | F35: Yes | G35: 系统时钟管理故障后无法输入给SPI， CAN ，ADC，WDG，GPIO， PWM，NVM时钟造成模块失效导致功能无法点亮，违背安全目标SG1,SG2.SG3 | H35: 1：支持硬线制动灯点亮： 2：支持停振检测，时钟异常时可以实时检测并尝试恢复 3：外部狗 | I35: SW_DFA_SM_001 SW_DFA_SM_002 SW_DFA_SM_004 | J35: 通过集成测试 | K35: 满足ASILB开发和测试
A36: =A3&"_"&B36 | B36: 32 | E36: – memory leaks 内存泄漏 | F36: not applicable
A37: =A3&"_"&B37 | B37: 33 | E37: – read/write access to memory allocated to another software element* —— 对分配给其他软件组件的内存的读/写访问权限* | F37: not applicable
A38: =A3&"_"&B38 | B38: 34 | E38: – buffer under-/overflow – 缓冲区下溢/上溢 | F38: not applicable
A39: =A3&"_"&B39 | B39: 35 | E39: • Timing and execution – deadlocks* 时机与执行 ——死锁* | F39: Yes | G39: 系统时钟管理故障后无法输入给SPI， CAN ，ADC，WDG，GPIO， PWM，NVM时钟造成模块失效导致功能无法点亮，违背安全目标SG1,SG2.SG3 | H39: 1：支持硬线制动灯点亮： 2：支持停振检测，时钟异常时可以实时检测并尝试恢复 | I39: SW_DFA_SM_001 SW_DFA_SM_002 | J39: 通过集成测试 | K39: 满足ASILB开发和测试
A40: =A3&"_"&B40 | B40: 36 | E40: – livelocks* 活锁 | F40: not applicable
A41: =A3&"_"&B41 | B41: 37 | E41: – incorrect allocation of execution time* ——执行时间分配不当* | F41: not applicable
...

Sheet Guide-Word
B1: Table E.1 shows examples for the selection of guide words applied to the design in Figure E.4. | K1: An example for a guide word of the signals A1 to An is shown in Table E.2

Sheet 安全机制
A1: 功能 | B1: SM ID | C1: 安全机制 | D1: Traceability | E1: 诊断覆盖率
A2: 制动转向 | B2: RL_SM_01 | C2: 电源监控器检测违反稳定电源的错误，以确保整个系统的供电，包括过压和欠压保护。此SM负责处理和诊断电源问题。 | D2: 制动转向 | E2: 60%
B3: RL_SM_02 | C3: 对来电信号进行检测，判断转向灯、制动灯是否满足开启要求；当来电信号错误，功能灯不响应，转向灯、制动灯各自进入安全状态（转向反馈、制动由车身检查）。 | D3: 制动转向 | E3: 60%
B4: RL_SM_03 | C4: 软件使用外部独立看门狗，当MCU软件故障可通过看门狗进行复位。 | D4: 制动转向 | E4: 90%
B5: RL_SM_04 | C5: 灯具内部做故障判断逻辑，当判断故障后进行反馈，反馈机制应遵循奇瑞标准。 | D5: 制动转向 | E5: 99%
B6: RL_SM_05 | C6: 当制动灯内部故障且故障无法反馈时，由车身进行电流检测以此判断制动灯故障状态。 | D6: 制动转向 | E6: 90%
B7: RL_SM_06 | C7: 制动灯采用N-1>=1方案进行设计，当某一组LED驱动或LED故障，剩余制动灯可以继续点亮。 | D7: 制动转向 | E7: 99%
B8: RL_SM_07 | C8: 转向灯采用N-1=0方案进行设计，当某一组LED驱动或LED故障，剩余转向灯熄灭。 | D8: 制动转向 | E8: 99%
B9: RL_SM_08 | C9: 在检测电路设计时，应考虑检测输出电压是否会导致MCU故障，故应使用钳位二极管将电压抑制在稳定区间。 | D9: 制动转向 | E9: 99%
B10: RL_SM_09 | C10: 芯片硬件支持自检，并利用芯片特性设计外围电路。 | D10: 制动转向 | E10: 90%
A12: SW DFA (软件) | B12: — | C12: 以下为 SW DFA 分析中引用的软件安全机制
B13: SW_DFA_SM_001 | C13: 支持硬线制动灯点亮 | D13: SG1-硬线制动灯冗余 | E13: —
B14: SW_DFA_SM_002 | C14: 支持停振检测 | D14: SG1/SG2/SG3-时钟停振检测 | E14: —
B15: SW_DFA_SM_003 | C15: 制动灯报文丢失200ms后点亮制动灯 | D15: SG1-报文丢失200ms制动灯点亮 | E15: —
B16: SW_DFA_SM_004 | C16: 支持外部看门狗 | D16: SG1/SG2/SG3-外部看门狗 | E16: —
B17: SW_DFA_SM_005 | C17: 连续10个周期BCC校验失败后会点亮制动灯 | D17: SG1-BCC校验失败制动灯点亮 | E17: —

Sheet 模版变更履历
A1: 模板变更履历 / Template Change History
A3: 版本Version | B3: 状态 Status | C3: 编制人Author | D3: 编制日期 Date | E3: 批准人Approver | F3: 批准日期Approve Date | G3: 内容描述 Description
A4: V0 | B4: Released | C4: 李超 | D4: 45503 | E4: 崔之文 | F4: 45503 | G4: 首次编制
